Workbook

Sheet Vehicle Specs
A1: Legend: Blue text = User Inputs | Green fill = Calculated | Yellow fill = Input Cells
A3: VEHICLE CONFIGURATION
A4: Parameter | B4: Symbol | C4: Unit | D4: Value | E4: Notes | F4: Remarks
A5: Seating Capacity | B5: n | C5: persons | D5: 3 | F5: Number of occupants the vehicle is designed to carry
A6: Passenger Weight (per person) | B6: m_p | C6: kg | D6: 75 | F6: Average weight assumed per occupant
A7: Max Speed (flat terrain) | B7: v_max | C7: km/h | D7: 70 | F7: Maximum vehicle speed on level ground
A8: Target Range | B8: R | C8: km | D8: 250 | F8: Desired driving range on a single charge
A10: WEIGHT SPECIFICATIONS
A11: Parameter | B11: Symbol | C11: Unit | D11: Value | E11: Notes | F11: Remarks
A12: Dry Weight (without battery) | B12: m_dry | C12: kg | D12: 475 | F12: Vehicle weight excluding battery pack
A13: LFP Pack Energy Density Factor | B13: k_lfp | C13: kg/kWh | D13: 8 | F13: Weight per unit energy at pack level for LFP chemistry (Modern packs achieve 5-5.5 kg/kWh or 200 Wh/kg)
A14: Battery Pack Weight | B14: m_batt | C14: kg | D14: =D13*D24 -> 143.52 | E14: k_lfp × E_batt | F14: Derived from energy capacity and LFP weight factor
A15: Curb Weight | B15: m_curb | C15: kg | D15: =D12+D14 -> 618.52 | E15: m_dry + m_batt | F15: Total vehicle weight without passengers
A16: Total Passenger Weight | B16: m_pass | C16: kg | D16: =D5*D6 -> 225 | E16: n × m_p | F16: Combined weight of all occupants
A17: Gross Vehicle Weight (GVW) | B17: GVW | C17: kg | D17: =D15+D16 -> 843.52 | E17: m_curb + m_pass | F17: Maximum loaded vehicle weight
A19: BATTERY SPECIFICATIONS
A20: Parameter | B20: Symbol | C20: Unit | D20: Value | E20: Notes | F20: Remarks
A21: Battery Chemistry | B21: — | C21: — | D21: LFP | F21: Battery cell chemistry type
A22: Nominal Voltage | B22: V_batt | C22: V | D22: 345 | F22: Total pack voltage based on cell count and series config
A23: Capacity | B23: C_batt | C23: Ah | D23: 52 | F23: Total pack amp-hour capacity
A24: Energy Capacity | B24: E_batt | C24: kWh | D24: =D22*D23/1000 -> 17.94 | E24: v × Ah / 1000 | F24: Total stored energy in the battery pack
A25: Usable Energy (80% DOD) | B25: E_use | C25: kWh | D25: =D24*0.8 -> 14.352 | E25: e_batt × DOD | F25: Energy available for driving after depth-of-discharge limit
A27: DRIVETRAIN PARAMETERS
A28: Parameter | B28: Symbol | C28: Unit | D28: Value | E28: Notes | F28: Remarks
A29: Wheel/Tyre Radius | B29: r | C29: m | D29: 0.29 | F29: Effective rolling radius including tyre deformation
A30: Gear Ratio (Transaxle) | B30: i | C30: :1 | D30: 12 | F30: Motor-to-wheel speed reduction ratio
A31: Powertrain Efficiency | B31: η | C31: — | D31: 0.88 | F31: Combined motor and gearbox efficiency
A32: Rolling Resistance Coeff | B32: Crr | C32: — | D32: 0.015 | F32: Tyre-road rolling friction coefficient
A33: Gravity | B33: g | C33: m/s² | D33: 9.81 | F33: Gravitational acceleration constant
A35: GRADEABILITY & OPERATING CONDITIONS
A36: Parameter | B36: Symbol | C36: Unit | D36: Value | E36: Notes | F36: Remarks
A37: Gradeability Angle | B37: θ_grade | C37: degrees | D37: 15 | F37: Maximum slope angle the vehicle must handle
A38: Target Speed on Grade | B38: v_grade | C38: km/h | D38: 5 | F38: Minimum speed to maintain while climbing
A39: Grade Climb Duration | B39: t_climb | C39: min | D39: 5 | F39: Maximum continuous climbing duration for sizing
A40: Duty Cycle Derating | B40: k_duty | C40: — | D40: =IF(D39<=1,0.4,IF(D39<=2,0.5,IF(D39<=5,0.7,1))) -> 0.7 | F40: Thermal derating factor based on climb duration
A41: Startup Acceleration | B41: a_start | C41: m/s² | D41: 0.5 | F41: Acceleration for hill start from standstill
A42: Static Friction Factor | B42: k_static | C42: — | D42: 1.2 | F42: Ratio of static to rolling friction for breakaway
A43: Grade % | B43: — | C43: % | D43: =TAN(RADIANS(D37))*100 -> 26.794919 | E43: TAN(θ)×100 | F43: Grade expressed as percentage slope
A45: VEHICLE DIMENSIONS
A46: Parameter | B46: Symbol | C46: Unit | D46: Value | E46: Notes | F46: Remarks
...

Sheet Gradeability Power
A1: Gradeability calculations for a single grade angle. All inputs linked from Vehicle Specs.
A3: LINKED INPUT PARAMETERS
A4: Parameter | B4: Symbol | C4: Unit | D4: Value | E4: Source | F4: Notes | G4: Remarks
A5: Gross Vehicle Weight | B5: GVW | C5: kg | D5: ='Vehicle Specs'!D17 -> 843.52 | E5: Vehicle Specs | G5: Full vehicle mass used for grade calculations
A6: Battery Voltage | B6: V | C6: V | D6: ='Vehicle Specs'!D22 -> 345 | E6: Vehicle Specs | G6: System voltage for current calculations
A7: Wheel Radius | B7: r | C7: m | D7: ='Vehicle Specs'!D29 -> 0.29 | E7: Vehicle Specs | G7: Effective tyre rolling radius
A8: Gear Ratio | B8: i | C8: :1 | D8: ='Vehicle Specs'!D30 -> 12 | E8: Vehicle Specs | G8: Motor-to-wheel reduction ratio
A9: Powertrain Efficiency | B9: η | C9: — | D9: ='Vehicle Specs'!D31 -> 0.88 | E9: Vehicle Specs | G9: Combined drivetrain efficiency
A10: Rolling Resistance | B10: Crr | C10: — | D10: ='Vehicle Specs'!D32 -> 0.015 | E10: Vehicle Specs | G10: Tyre-road friction coefficient
A11: Gravity | B11: g | C11: m/s² | D11: ='Vehicle Specs'!D33 -> 9.81 | E11: Vehicle Specs | G11: Gravitational acceleration
A12: Grade Angle | B12: θ | C12: ° | D12: ='Vehicle Specs'!D37 -> 15 | E12: Vehicle Specs | G12: Slope angle for gradeability sizing
A13: Speed on Grade | B13: v | C13: km/h | D13: ='Vehicle Specs'!D38 -> 5 | E13: Vehicle Specs | G13: Target climbing speed
A14: Duty Cycle Factor | B14: k_duty | C14: — | D14: ='Vehicle Specs'!D40 -> 0.7 | E14: Vehicle Specs | G14: Thermal derating based on climb duration
A15: Startup Acceleration | B15: a | C15: m/s² | D15: ='Vehicle Specs'!D41 -> 0.5 | E15: Vehicle Specs | G15: Acceleration for starting from rest on slope
A16: Static Friction Factor | B16: k_static | C16: — | D16: ='Vehicle Specs'!D42 -> 1.2 | E16: Vehicle Specs | G16: Breakaway friction multiplier vs rolling
A18: SUSTAINED CLIMBING (Constant Speed on Grade)
A19: Parameter | B19: Symbol | C19: Unit | D19: Value | E19: Source | F19: Notes | G19: Remarks
A20: Grade Angle | B20: θ | C20: rad | D20: =RADIANS(D12) -> 0.26179939 | G20: Grade angle converted to radians for trig functions
A21: sin(θ) | B21: — | C21: — | D21: =SIN(D20) -> 0.25881905 | G21: Sine component for gravity force along slope
A22: cos(θ) | B22: — | C22: — | D22: =COS(D20) -> 0.96592583 | G22: Cosine component for normal force on slope
A23: Grade Resistance | B23: Fg | C23: N | D23: =D5*D11*D21 -> 2141.7098 | E23: gvw×g×sin(θ) | G23: Force of gravity pulling vehicle down the slope
A24: Rolling Resistance | B24: Fr | C24: N | D24: =D5*D11*D10*D22 -> 119.89455 | E24: gvw×g×Crr×cos(θ) | G24: Tyre friction force, reduced slightly on slopes
A25: Total Tractive Force (Climb) | B25: Ft | C25: N | D25: =D23+D24 -> 2261.6043 | E25: fg+fr | G25: Combined resistance force during steady climbing
A26: Speed | B26: v | C26: m/s | D26: =D13/3.6 -> 1.3888889 | G26: Climbing speed converted to m/s
A27: Wheel Torque | B27: Tw | C27: Nm | D27: =D25*D7 -> 655.86526 | E27: ft×r | G27: Torque required at the wheel to overcome climb forces
A28: Motor Torque (Sustained) | B28: Tm_climb | C28: Nm | D28: =D27/(D8*D9) -> 62.108452 | E28: tw/(i×η)) | G28: Motor shaft torque for sustained climbing
A29: Power at Wheel | B29: Pw | C29: W | D29: =D25*D26 -> 3141.1171 | E29: ft×v | G29: Mechanical power at wheel surface
A30: Electrical Power (Climb) | B30: Pe_climb | C30: W | D30: =D29/D9 -> 3569.4513 | E30: pw/η | G30: Electrical power drawn from battery during climb
A31: Electrical Power (Climb) | B31: Pe_climb | C31: kW | D31: =D30/1000 -> 3.5694513 | G31: Same as above in kilowatts
A32: Motor Current (Climb) | B32: I_climb | C32: A | D32: =D30/D6 -> 10.346236 | E32: pe/v | G32: Battery current during sustained climbing
A34: STARTUP ON GRADE (Peak — Starting from Standstill)
A35: Parameter | B35: Symbol | C35: Unit | D35: Value | E35: Source | F35: Notes | G35: Remarks
A36: Grade Force | B36: Fg | C36: N | D36: =D23 -> 2141.7098 | G36: Same gravity component as sustained climb
A37: Rolling (Static) | B37: Fr_s | C37: N | D37: =D24*D16 -> 143.87346 | E37: fr×k_static | G37: Higher breakaway friction when starting from rest
A38: Acceleration Force | B38: Fa | C38: N | D38: =D5*D15 -> 421.76 | E38: gvw×a | G38: Force needed to accelerate from standstill on slope
A39: Peak Tractive Force | B39: Ft_peak | C39: N | D39: =D36+D37+D38 -> 2707.3432 | E39: fg+fr_s+fa | G39: Total force for worst-case hill start
A40: Peak Wheel Torque | B40: Tw_peak | C40: Nm | D40: =D39*D7 -> 785.12954 | E40: ft_peak×r | G40: Wheel torque for hill start
A41: Peak Motor Torque | B41: Tm_peak | C41: Nm | D41: =D40/(D8*D9) -> 74.349388 | E41: tw/(i×η)) | G41: Motor shaft torque for hill start
A42: Peak Power | B42: Pp | C42: W | D42: =D39*D26 -> 3760.199 | E42: ft_peak×v | G42: Instantaneous mechanical power for hill start
A43: Peak Elec Power | B43: Pe_peak | C43: kW | D43: =D42/(D9*1000) -> 4.2729534 | E43: pp/η | G43: Electrical power for hill start
...

Sheet Acceleration Power
A1: Acceleration power calculations. All inputs linked from Vehicle Specs.
A3: LINKED INPUT PARAMETERS
A4: Parameter | B4: Symbol | C4: Unit | D4: Value | E4: Source | K4: Remarks
A5: Acceleration Mass | B5: m_accel | C5: kg | D5: ='Vehicle Specs'!D68 -> 693.52 | E5: Vehicle Specs | K5: Vehicle mass for acceleration (driver only)
A6: Wheel Radius | B6: r | C6: m | D6: ='Vehicle Specs'!D29 -> 0.29 | E6: Vehicle Specs | K6: Effective tyre rolling radius
A7: Gear Ratio | B7: i | C7: :1 | D7: ='Vehicle Specs'!D30 -> 12 | E7: Vehicle Specs | K7: Motor-to-wheel reduction ratio
A8: Powertrain Efficiency | B8: η | C8: — | D8: ='Vehicle Specs'!D31 -> 0.88 | E8: Vehicle Specs | K8: Combined drivetrain efficiency
A9: Rolling Resistance | B9: Crr | C9: — | D9: ='Vehicle Specs'!D32 -> 0.015 | E9: Vehicle Specs | K9: tyre-road friction coefficient
A10: Gravity | B10: g | C10: m/s² | D10: ='Vehicle Specs'!D33 -> 9.81 | E10: Vehicle Specs | K10: Gravitational acceleration
A11: Battery Voltage | B11: V_batt | C11: V | D11: ='Vehicle Specs'!D22 -> 345 | E11: Vehicle Specs | K11: System voltage for current calculation
A12: Air Density | B12: ρ | C12: kg/m³ | D12: ='Vehicle Specs'!D54 -> 1.225 | E12: Vehicle Specs | K12: Standard air density
A13: Drag Coefficient | B13: Cd | C13: — | D13: ='Vehicle Specs'!D55 -> 0.35 | E13: Vehicle Specs | K13: Aerodynamic shape factor
A14: Frontal Area | B14: A_f | C14: m² | D14: ='Vehicle Specs'!D50 -> 1.704 | E14: Vehicle Specs | K14: Projected frontal area
A16: ACCELERATION PROFILE (from Vehicle Specs)
A17: Segment | B17: Start (km/h) | C17: End (km/h) | D17: Seg Time (s) | E17: Seg Accel (m/s²) | F17: Start (m/s) | G17: End (m/s) | K17: Remarks
A18: Segment 1 | B18: 0 | C18: ='Vehicle Specs'!A59 -> 20 | D18: ='Vehicle Specs'!C59 -> 3 | E18: ='Vehicle Specs'!D59 -> 1.8518519 | F18: =B18/3.6 -> 0 | G18: =C18/3.6 -> 5.5555556 | K18: Speed segment linked from acceleration targets
A19: Segment 2 | B19: ='Vehicle Specs'!A59 -> 20 | C19: ='Vehicle Specs'!A60 -> 30 | D19: ='Vehicle Specs'!C60 -> 1.5 | E19: ='Vehicle Specs'!D60 -> 1.8518519 | F19: =B19/3.6 -> 5.5555556 | G19: =C19/3.6 -> 8.3333333 | K19: Speed segment linked from acceleration targets
A20: Segment 3 | B20: ='Vehicle Specs'!A60 -> 30 | C20: ='Vehicle Specs'!A61 -> 40 | D20: ='Vehicle Specs'!C61 -> 1.5 | E20: ='Vehicle Specs'!D61 -> 1.8518519 | F20: =B20/3.6 -> 8.3333333 | G20: =C20/3.6 -> 11.111111 | K20: Speed segment linked from acceleration targets
A21: Segment 4 | B21: ='Vehicle Specs'!A61 -> 40 | C21: ='Vehicle Specs'!A62 -> 50 | D21: ='Vehicle Specs'!C62 -> 2 | E21: ='Vehicle Specs'!D62 -> 1.3888889 | F21: =B21/3.6 -> 11.111111 | G21: =C21/3.6 -> 13.888889 | K21: Speed segment linked from acceleration targets
A22: Segment 5 | B22: ='Vehicle Specs'!A62 -> 50 | C22: ='Vehicle Specs'!A63 -> 60 | D22: ='Vehicle Specs'!C63 -> 3 | E22: ='Vehicle Specs'!D63 -> 0.92592593 | F22: =B22/3.6 -> 13.888889 | G22: =C22/3.6 -> 16.666667 | K22: Speed segment linked from acceleration targets
A23: Segment 6 | B23: ='Vehicle Specs'!A63 -> 60 | C23: ='Vehicle Specs'!A64 -> 70 | D23: ='Vehicle Specs'!C64 -> 3 | E23: ='Vehicle Specs'!D64 -> 0.92592593 | F23: =B23/3.6 -> 16.666667 | G23: =C23/3.6 -> 19.444444 | K23: Speed segment linked from acceleration targets
A25: FORCE & POWER AT SEGMENT END SPEED
A26: Segment | B26: End Speed (m/s) | C26: F_accel (N) | D26: F_roll (N) | E26: F_aero (N) | F26: F_total (N) | G26: P_mech (kW) | H26: P_elec (kW) | I26: Motor Torque (Nm) | J26: Motor Current (A) | K26: Remarks
A27: Segment 1 | B27: =G18 -> 5.5555556 | C27: =$D$5*E18 -> 1284.2963 | D27: =$D$9*$D$5*$D$10 -> 102.05147 | E27: =0.5*$D$12*$D$13*$D$14*B27^2 -> 11.274537 | F27: =C27+D27+E27 -> 1397.6223 | G27: =F27*B27/1000 -> 7.7645683 | H27: =G27/$D$8 -> 8.8233731 | I27: =(F27*$D$6)/($D$8*$D$7) -> 38.381673 | J27: =H27*1000/$D$11 -> 25.574995 | K27: Forces and power at segment end speed
A28: Segment 2 | B28: =G19 -> 8.3333333 | C28: =$D$5*E19 -> 1284.2963 | D28: =$D$9*$D$5*$D$10 -> 102.05147 | E28: =0.5*$D$12*$D$13*$D$14*B28^2 -> 25.367708 | F28: =C28+D28+E28 -> 1411.7155 | G28: =F28*B28/1000 -> 11.764296 | H28: =G28/$D$8 -> 13.368518 | I28: =(F28*$D$6)/($D$8*$D$7) -> 38.768701 | J28: =H28*1000/$D$11 -> 38.749327
A29: Segment 3 | B29: =G20 -> 11.111111 | C29: =$D$5*E20 -> 1284.2963 | D29: =$D$9*$D$5*$D$10 -> 102.05147 | E29: =0.5*$D$12*$D$13*$D$14*B29^2 -> 45.098148 | F29: =C29+D29+E29 -> 1431.4459 | G29: =F29*B29/1000 -> 15.904955 | H29: =G29/$D$8 -> 18.073812 | I29: =(F29*$D$6)/($D$8*$D$7) -> 39.310541 | J29: =H29*1000/$D$11 -> 52.387861
A30: Segment 4 | B30: =G21 -> 13.888889 | C30: =$D$5*E21 -> 963.22222 | D30: =$D$9*$D$5*$D$10 -> 102.05147 | E30: =0.5*$D$12*$D$13*$D$14*B30^2 -> 70.465856 | F30: =C30+D30+E30 -> 1135.7395 | G30: =F30*B30/1000 -> 15.77416 | H30: =G30/$D$8 -> 17.925182 | I30: =(F30*$D$6)/($D$8*$D$7) -> 31.189817 | J30: =H30*1000/$D$11 -> 51.95705
A31: Segment 5 | B31: =G22 -> 16.666667 | C31: =$D$5*E22 -> 642.14815 | D31: =$D$9*$D$5*$D$10 -> 102.05147 | E31: =0.5*$D$12*$D$13*$D$14*B31^2 -> 101.47083 | F31: =C31+D31+E31 -> 845.67045 | G31: =F31*B31/1000 -> 14.094507 | H31: =G31/$D$8 -> 16.016486 | I31: =(F31*$D$6)/($D$8*$D$7) -> 23.223904 | J31: =H31*1000/$D$11 -> 46.424596
A32: Segment 6 | B32: =G23 -> 19.444444 | C32: =$D$5*E23 -> 642.14815 | D32: =$D$9*$D$5*$D$10 -> 102.05147 | E32: =0.5*$D$12*$D$13*$D$14*B32^2 -> 138.11308 | F32: =C32+D32+E32 -> 882.31269 | G32: =F32*B32/1000 -> 17.15608 | H32: =G32/$D$8 -> 19.495546 | I32: =(F32*$D$6)/($D$8*$D$7) -> 24.230178 | J32: =H32*1000/$D$11 -> 56.508828
A34: AVERAGE POWER PER SEGMENT (Energy Method)
A35: Segment | B35: ΔKE (J) | C35: Seg Time (s) | D35: P_accel (kW) | E35: P_roll_avg (kW) | F35: P_aero_avg (kW) | G35: P_mech_avg (kW) | H35: P_elec_avg (kW) | K35: Remarks
A36: Segment 1 | B36: =0.5*$D$5*(G18^2-F18^2) -> 10702.469 | C36: =D18 -> 3 | D36: =B36/C36/1000 -> 3.5674897 | E36: =$D$9*$D$5*$D$10*(F18+G18)/2/1000 -> 0.2834763 | F36: =0.5*$D$12*$D$13*$D$14*((F18+G18)/2)^2*((F18+G18)/2)/1000 -> 0.0078295396 | G36: =D36+E36+F36 -> 3.8587956 | H36: =G36/$D$8 -> 4.3849949 | K36: Average power using kinetic energy method
A37: Segment 2 | B37: =0.5*$D$5*(G19^2-F19^2) -> 13378.086 | C37: =D19 -> 1.5 | D37: =B37/C37/1000 -> 8.9187243 | E37: =$D$9*$D$5*$D$10*(F19+G19)/2/1000 -> 0.70869075 | F37: =0.5*$D$12*$D$13*$D$14*((F19+G19)/2)^2*((F19+G19)/2)/1000 -> 0.12233656 | G37: =D37+E37+F37 -> 9.7497516 | H37: =G37/$D$8 -> 11.079263
A38: Segment 3 | B38: =0.5*$D$5*(G20^2-F20^2) -> 18729.321 | C38: =D20 -> 1.5 | D38: =B38/C38/1000 -> 12.486214 | E38: =$D$9*$D$5*$D$10*(F20+G20)/2/1000 -> 0.99216705 | F38: =0.5*$D$12*$D$13*$D$14*((F20+G20)/2)^2*((F20+G20)/2)/1000 -> 0.33569151 | G38: =D38+E38+F38 -> 13.814073 | H38: =G38/$D$8 -> 15.69781
A39: Segment 4 | B39: =0.5*$D$5*(G21^2-F21^2) -> 24080.556 | C39: =D21 -> 2 | D39: =B39/C39/1000 -> 12.040278 | E39: =$D$9*$D$5*$D$10*(F21+G21)/2/1000 -> 1.2756433 | F39: =0.5*$D$12*$D$13*$D$14*((F21+G21)/2)^2*((F21+G21)/2)/1000 -> 0.7134668 | G39: =D39+E39+F39 -> 14.029388 | H39: =G39/$D$8 -> 15.942486
A40: Segment 5 | B40: =0.5*$D$5*(G22^2-F22^2) -> 29431.79 | C40: =D22 -> 3 | D40: =B40/C40/1000 -> 9.8105967 | E40: =$D$9*$D$5*$D$10*(F22+G22)/2/1000 -> 1.5591197 | F40: =0.5*$D$12*$D$13*$D$14*((F22+G22)/2)^2*((F22+G22)/2)/1000 -> 1.3026397 | G40: =D40+E40+F40 -> 12.672356 | H40: =G40/$D$8 -> 14.400405
A41: Segment 6 | B41: =0.5*$D$5*(G23^2-F23^2) -> 34783.025 | C41: =D23 -> 3 | D41: =B41/C41/1000 -> 11.594342 | E41: =$D$9*$D$5*$D$10*(F23+G23)/2/1000 -> 1.842596 | F41: =0.5*$D$12*$D$13*$D$14*((F23+G23)/2)^2*((F23+G23)/2)/1000 -> 2.1501873 | G41: =D41+E41+F41 -> 15.587125 | H41: =G41/$D$8 -> 17.712642
A43: ACCELERATION POWER SUMMARY
A44: Parameter | B44: Value | C44: Unit | D44: Source | K44: Remarks
A45: Peak Instantaneous Mech Power | B45: =MAX(G27:G32) -> 17.15608 | C45: kW | D45: Max across all segments | K45: Highest mechanical power at any segment end speed
...

Sheet Powertrain Summary
A1: Powertrain Statement of Requirements (SOR) — motor, controller, gearbox, and battery specifications.
A3: PEAK RATING — Motor Sizing (max across gradeability & acceleration)
A4: Parameter | B4: Unit | C4: Gradeability | D4: Acceleration | E4: PEAK (Max) | F4: Governed By | G4: Duration | H4: Margin | I4: Remarks
A5: Peak Power | B5: kW | C5: ='Gradeability Power'!D52 -> 4.2729534 | D5: ='Acceleration Power'!B46 -> 19.495546 | E5: =MAX(C5,D5) -> 19.495546 | F5: =IF(D5>=C5,"Acceleration","Gradeability") -> Acceleration | G5: 10 sec | I5: Maximum power requirement across both scenarios
A6: Peak Torque | B6: Nm | C6: ='Gradeability Power'!D41 -> 74.349388 | D6: ='Acceleration Power'!B47 -> 39.310541 | E6: =MAX(C6,D6) -> 74.349388 | F6: =IF(D6>=C6,"Acceleration","Gradeability") -> Gradeability | G6: 10 sec | I6: Maximum torque requirement across both scenarios
A7: Peak Current | B7: A | C7: ='Gradeability Power'!D44 -> 12.385372 | D7: ='Acceleration Power'!B48 -> 56.508828 | E7: =MAX(C7,D7) -> 56.508828 | F7: =IF(D7>=C7,"Acceleration","Gradeability") -> Acceleration | G7: 10 sec | I7: Maximum current requirement across both scenarios
A9: NOMINAL RATING — City Driving
A10: Parameter | B10: Unit | C10: Value | F10: Formula | I10: Remarks
A11: Nominal Speed | B11: km/h | C11: 40 | I11: Typical city cruising speed for continuous rating
A12: Nominal Acceleration | B12: m/s² | C12: 0.5 | I12: Gentle acceleration for everyday driving
A13: Vehicle Mass (GVW) | B13: kg | C13: ='Vehicle Specs'!D17 -> 843.52 | I13: Full passenger load for nominal calculations
A14: Nominal Accel Force | B14: N | C14: =C13*C12 -> 421.76 | F14: m x a | I14: Force for gentle city acceleration
A15: Nominal Rolling Resistance | B15: N | C15: ='Vehicle Specs'!D32*C13*'Vehicle Specs'!D33 -> 124.12397 | F15: Crr x m x g | I15: Rolling friction on flat road
A16: Nominal Aero Drag | B16: N | C16: =0.5*'Vehicle Specs'!D54*'Vehicle Specs'!D55*'Vehicle Specs'!D50*(C11/3.6)^2 -> 45.098148 | F16: 0.5*rho*Cd*Af*v^2 | I16: Aerodynamic drag at city speed
A17: Nominal Total Force | B17: N | C17: =C14+C15+C16 -> 590.98212 | F17: Sum of forces | I17: Total resistance force at city speed
A18: Nominal Elec Power | B18: kW | C18: =C17*(C11/3.6)/1000/'Vehicle Specs'!D31 -> 7.4618954 | F18: F*v / eta | I18: Electrical power for city driving
A19: Nominal Motor Torque | B19: Nm | C19: =(C17*'Vehicle Specs'!D29)/('Vehicle Specs'!D31*'Vehicle Specs'!D30) -> 16.229623 | F19: (F*r)/(eta*i) | I19: Motor torque for city driving
A20: Nominal Motor Current | B20: A | C20: =C18*1000/'Vehicle Specs'!D22 -> 21.628682 | F20: P / V | I20: Motor current for city driving
A22: RECOMMENDED MOTOR SPECIFICATIONS
A23: Parameter | B23: Unit | C23: Required | D23: Margin | E23: Rated Value | F23: Duration | G23: Governed By | I23: Remarks
A24: Motor Type | C24: PMSM | I24: Permanent Magnet Synchronous Motor
A25: Rated Voltage | B25: V | C25: ='Vehicle Specs'!D22 -> 345 | I25: Must match battery pack voltage
A26: Peak Power | B26: kW | C26: =E5 -> 19.495546 | D26: 15% | E26: =C26*1.15 -> 22.419878 | F26: 10 sec | G26: =F5 -> Acceleration | I26: Peak power with safety margin
A27: Nominal Power | B27: kW | C27: =C18 -> 7.4618954 | D27: 15% | E27: =C27*1.15 -> 8.5811797 | F27: Continuous | G27: City driving | I27: Continuous thermal power rating
A28: Peak Torque | B28: Nm | C28: =E6 -> 74.349388 | D28: 15% | E28: =C28*1.15 -> 85.501797 | F28: 10 sec | G28: =F6 -> Gradeability | I28: Peak torque with safety margin
A29: Nominal Torque | B29: Nm | C29: =C19 -> 16.229623 | D29: 15% | E29: =C29*1.15 -> 18.664066 | F29: Continuous | G29: City driving | I29: Continuous thermal torque rating
A30: Cooling | C30: Air Cooled | I30: Cooling method based on power level
A31: Protection | C31: IP67 | I31: Ingress protection rating
A33: RECOMMENDED CONTROLLER SPECIFICATIONS
A34: Parameter | B34: Unit | C34: Required | D34: Margin | E34: Rated Value | F34: Duration | G34: Governed By | I34: Remarks
A35: Controller Type | C35: FOC | I35: Field Oriented Control for PMSM motors
A36: Operating Voltage | B36: V | C36: ='Vehicle Specs'!D22 -> 345 | I36: Must match motor and battery voltage
A37: Peak Current | B37: A | C37: =E7 -> 56.508828 | D37: 10% | E37: =ROUNDUP(C37*1.1,-1) -> 70 | F37: 10 sec | G37: =F7 -> Acceleration | I37: Peak current with margin, rounded up
A38: Nominal Current | B38: A | C38: =C20 -> 21.628682 | D38: 10% | E38: =ROUNDUP(C38*1.1,-1) -> 30 | F38: Continuous | G38: City driving | I38: Continuous current rating
A39: Regen Braking | C39: Yes | I39: Regenerative braking capability
A41: RECOMMENDED GEARBOX / TRANSAXLE
A42: Parameter | B42: Unit | C42: Required | D42: Margin | E42: Rated Value | G42: Governed By | I42: Remarks
A43: Type | C43: Single Speed | I43: Fixed reduction gearbox
A44: Gear Ratio | B44: :1 | C44: ='Vehicle Specs'!D30 -> 12 | I44: Motor-to-wheel reduction ratio
A45: Input Torque Capacity | B45: Nm | C45: =E6 -> 74.349388 | D45: 10% | E45: =ROUNDUP(C45*1.1,-1) -> 90 | G45: =F6 -> Gradeability | I45: Must handle peak motor torque
...

Sheet Accel Verification
A1: Reverse acceleration check using rated motor specifications. Verifies achievable 0-70 km/h times.
A3: RATED MOTOR SPECIFICATIONS (from Powertrain Summary)
A4: Parameter | B4: Unit | C4: Value | M4: Remarks
A5: Peak Motor Power (rated) | B5: kW | C5: ='Powertrain Summary'!E26 -> 22.419878 | M5: Rated peak power from motor specs
A6: Peak Motor Torque (rated) | B6: Nm | C6: ='Powertrain Summary'!E28 -> 85.501797 | M6: Rated peak torque from motor specs
A7: Acceleration Mass (driver only) | B7: kg | C7: ='Vehicle Specs'!D68 -> 693.52 | M7: Vehicle mass for acceleration (driver only)
A9: SPEED-BY-SPEED REVERSE CALCULATION
A10: Speed (km/h) | B10: Speed (m/s) | C10: F_torque (N) | D10: F_power (N) | E10: F_avail (N) | F10: F_roll (N) | G10: F_aero (N) | H10: F_net (N) | I10: Accel (m/s²) | J10: Limiting | K10: Δv (m/s) | L10: Δt (s) | M10: Cumul Time (s)
A11: 0 | B11: =MAX(A11/3.6, 0.1) -> 0.1 | C11: =C$6*'Vehicle Specs'!D30*'Vehicle Specs'!D31/'Vehicle Specs'!D29 -> 3113.4447 | D11: =C$5*1000*'Vehicle Specs'!D31/B11 -> 197294.92 | E11: =MIN(C11,D11) -> 3113.4447 | F11: ='Vehicle Specs'!D32*C$7*'Vehicle Specs'!D33 -> 102.05147 | G11: =0.5*'Vehicle Specs'!D54*'Vehicle Specs'!D55*'Vehicle Specs'!D50*B11^2 -> 0.00365295 | H11: =MAX(E11-F11-G11, 0) -> 3011.3896 | I11: =IF(H11>0, H11/C$7, 0) -> 4.3421814 | J11: =IF(H11=0,"Cannot accel",IF(C11<=D11,"Torque","Power")) -> Torque | K11: 0 | L11: 0 | M11: 0
A12: 5 | B12: =MAX(A12/3.6, 0.1) -> 1.3888889 | C12: =C$6*'Vehicle Specs'!D30*'Vehicle Specs'!D31/'Vehicle Specs'!D29 -> 3113.4447 | D12: =C$5*1000*'Vehicle Specs'!D31/B12 -> 14205.234 | E12: =MIN(C12,D12) -> 3113.4447 | F12: ='Vehicle Specs'!D32*C$7*'Vehicle Specs'!D33 -> 102.05147 | G12: =0.5*'Vehicle Specs'!D54*'Vehicle Specs'!D55*'Vehicle Specs'!D50*B12^2 -> 0.70465856 | H12: =MAX(E12-F12-G12, 0) -> 3010.6886 | I12: =IF(H12>0, H12/C$7, 0) -> 4.3411706 | J12: =IF(H12=0,"Cannot accel",IF(C12<=D12,"Torque","Power")) -> Torque | K12: =B12-B11 -> 1.2888889 | L12: =IF(I12+I11>0, 2*K12/(I12+I11), 999) -> 0.29686437 | M12: =M11+L12 -> 0.29686437
A13: 10 | B13: =MAX(A13/3.6, 0.1) -> 2.7777778 | C13: =C$6*'Vehicle Specs'!D30*'Vehicle Specs'!D31/'Vehicle Specs'!D29 -> 3113.4447 | D13: =C$5*1000*'Vehicle Specs'!D31/B13 -> 7102.6172 | E13: =MIN(C13,D13) -> 3113.4447 | F13: ='Vehicle Specs'!D32*C$7*'Vehicle Specs'!D33 -> 102.05147 | G13: =0.5*'Vehicle Specs'!D54*'Vehicle Specs'!D55*'Vehicle Specs'!D50*B13^2 -> 2.8186343 | H13: =MAX(E13-F13-G13, 0) -> 3008.5746 | I13: =IF(H13>0, H13/C$7, 0) -> 4.3381224 | J13: =IF(H13=0,"Cannot accel",IF(C13<=D13,"Torque","Power")) -> Torque | K13: =B13-B12 -> 1.3888889 | L13: =IF(I13+I12>0, 2*K13/(I13+I12), 999) -> 0.32004655 | M13: =M12+L13 -> 0.61691092
A14: 15 | B14: =MAX(A14/3.6, 0.1) -> 4.1666667 | C14: =C$6*'Vehicle Specs'!D30*'Vehicle Specs'!D31/'Vehicle Specs'!D29 -> 3113.4447 | D14: =C$5*1000*'Vehicle Specs'!D31/B14 -> 4735.0781 | E14: =MIN(C14,D14) -> 3113.4447 | F14: ='Vehicle Specs'!D32*C$7*'Vehicle Specs'!D33 -> 102.05147 | G14: =0.5*'Vehicle Specs'!D54*'Vehicle Specs'!D55*'Vehicle Specs'!D50*B14^2 -> 6.3419271 | H14: =MAX(E14-F14-G14, 0) -> 3005.0513 | I14: =IF(H14>0, H14/C$7, 0) -> 4.3330421 | J14: =IF(H14=0,"Cannot accel",IF(C14<=D14,"Torque","Power")) -> Torque | K14: =B14-B13 -> 1.3888889 | L14: =IF(I14+I13>0, 2*K14/(I14+I13), 999) -> 0.32034657 | M14: =M13+L14 -> 0.93725749
A15: 20 | B15: =MAX(A15/3.6, 0.1) -> 5.5555556 | C15: =C$6*'Vehicle Specs'!D30*'Vehicle Specs'!D31/'Vehicle Specs'!D29 -> 3113.4447 | D15: =C$5*1000*'Vehicle Specs'!D31/B15 -> 3551.3086 | E15: =MIN(C15,D15) -> 3113.4447 | F15: ='Vehicle Specs'!D32*C$7*'Vehicle Specs'!D33 -> 102.05147 | G15: =0.5*'Vehicle Specs'!D54*'Vehicle Specs'!D55*'Vehicle Specs'!D50*B15^2 -> 11.274537 | H15: =MAX(E15-F15-G15, 0) -> 3000.1187 | I15: =IF(H15>0, H15/C$7, 0) -> 4.3259296 | J15: =IF(H15=0,"Cannot accel",IF(C15<=D15,"Torque","Power")) -> Torque | K15: =B15-B14 -> 1.3888889 | L15: =IF(I15+I14>0, 2*K15/(I15+I14), 999) -> 0.32079765 | M15: =M14+L15 -> 1.2580551
A16: 25 | B16: =MAX(A16/3.6, 0.1) -> 6.9444444 | C16: =C$6*'Vehicle Specs'!D30*'Vehicle Specs'!D31/'Vehicle Specs'!D29 -> 3113.4447 | D16: =C$5*1000*'Vehicle Specs'!D31/B16 -> 2841.0469 | E16: =MIN(C16,D16) -> 2841.0469 | F16: ='Vehicle Specs'!D32*C$7*'Vehicle Specs'!D33 -> 102.05147 | G16: =0.5*'Vehicle Specs'!D54*'Vehicle Specs'!D55*'Vehicle Specs'!D50*B16^2 -> 17.616464 | H16: =MAX(E16-F16-G16, 0) -> 2721.3789 | I16: =IF(H16>0, H16/C$7, 0) -> 3.9240093 | J16: =IF(H16=0,"Cannot accel",IF(C16<=D16,"Torque","Power")) -> Power | K16: =B16-B15 -> 1.3888889 | L16: =IF(I16+I15>0, 2*K16/(I16+I15), 999) -> 0.33670283 | M16: =M15+L16 -> 1.594758
A17: 30 | B17: =MAX(A17/3.6, 0.1) -> 8.3333333 | C17: =C$6*'Vehicle Specs'!D30*'Vehicle Specs'!D31/'Vehicle Specs'!D29 -> 3113.4447 | D17: =C$5*1000*'Vehicle Specs'!D31/B17 -> 2367.5391 | E17: =MIN(C17,D17) -> 2367.5391 | F17: ='Vehicle Specs'!D32*C$7*'Vehicle Specs'!D33 -> 102.05147 | G17: =0.5*'Vehicle Specs'!D54*'Vehicle Specs'!D55*'Vehicle Specs'!D50*B17^2 -> 25.367708 | H17: =MAX(E17-F17-G17, 0) -> 2240.1199 | I17: =IF(H17>0, H17/C$7, 0) -> 3.2300725 | J17: =IF(H17=0,"Cannot accel",IF(C17<=D17,"Torque","Power")) -> Power | K17: =B17-B16 -> 1.3888889 | L17: =IF(I17+I16>0, 2*K17/(I17+I16), 999) -> 0.38827873 | M17: =M16+L17 -> 1.9830367
A18: 35 | B18: =MAX(A18/3.6, 0.1) -> 9.7222222 | C18: =C$6*'Vehicle Specs'!D30*'Vehicle Specs'!D31/'Vehicle Specs'!D29 -> 3113.4447 | D18: =C$5*1000*'Vehicle Specs'!D31/B18 -> 2029.3192 | E18: =MIN(C18,D18) -> 2029.3192 | F18: ='Vehicle Specs'!D32*C$7*'Vehicle Specs'!D33 -> 102.05147 | G18: =0.5*'Vehicle Specs'!D54*'Vehicle Specs'!D55*'Vehicle Specs'!D50*B18^2 -> 34.52827 | H18: =MAX(E18-F18-G18, 0) -> 1892.7395 | I18: =IF(H18>0, H18/C$7, 0) -> 2.7291779 | J18: =IF(H18=0,"Cannot accel",IF(C18<=D18,"Torque","Power")) -> Power | K18: =B18-B17 -> 1.3888889 | L18: =IF(I18+I17>0, 2*K18/(I18+I17), 999) -> 0.46612872 | M18: =M17+L18 -> 2.4491654
A19: 40 | B19: =MAX(A19/3.6, 0.1) -> 11.111111 | C19: =C$6*'Vehicle Specs'!D30*'Vehicle Specs'!D31/'Vehicle Specs'!D29 -> 3113.4447 | D19: =C$5*1000*'Vehicle Specs'!D31/B19 -> 1775.6543 | E19: =MIN(C19,D19) -> 1775.6543 | F19: ='Vehicle Specs'!D32*C$7*'Vehicle Specs'!D33 -> 102.05147 | G19: =0.5*'Vehicle Specs'!D54*'Vehicle Specs'!D55*'Vehicle Specs'!D50*B19^2 -> 45.098148 | H19: =MAX(E19-F19-G19, 0) -> 1628.5047 | I19: =IF(H19>0, H19/C$7, 0) -> 2.3481726 | J19: =IF(H19=0,"Cannot accel",IF(C19<=D19,"Torque","Power")) -> Power | K19: =B19-B18 -> 1.3888889 | L19: =IF(I19+I18>0, 2*K19/(I19+I18), 999) -> 0.54709198 | M19: =M18+L19 -> 2.9962574
A20: 45 | B20: =MAX(A20/3.6, 0.1) -> 12.5 | C20: =C$6*'Vehicle Specs'!D30*'Vehicle Specs'!D31/'Vehicle Specs'!D29 -> 3113.4447 | D20: =C$5*1000*'Vehicle Specs'!D31/B20 -> 1578.3594 | E20: =MIN(C20,D20) -> 1578.3594 | F20: ='Vehicle Specs'!D32*C$7*'Vehicle Specs'!D33 -> 102.05147 | G20: =0.5*'Vehicle Specs'!D54*'Vehicle Specs'!D55*'Vehicle Specs'!D50*B20^2 -> 57.077344 | H20: =MAX(E20-F20-G20, 0) -> 1419.2306 | I20: =IF(H20>0, H20/C$7, 0) -> 2.0464162 | J20: =IF(H20=0,"Cannot accel",IF(C20<=D20,"Torque","Power")) -> Power | K20: =B20-B19 -> 1.3888889 | L20: =IF(I20+I19>0, 2*K20/(I20+I19), 999) -> 0.63209048 | M20: =M19+L20 -> 3.6283479
A21: 50 | B21: =MAX(A21/3.6, 0.1) -> 13.888889 | C21: =C$6*'Vehicle Specs'!D30*'Vehicle Specs'!D31/'Vehicle Specs'!D29 -> 3113.4447 | D21: =C$5*1000*'Vehicle Specs'!D31/B21 -> 1420.5234 | E21: =MIN(C21,D21) -> 1420.5234 | F21: ='Vehicle Specs'!D32*C$7*'Vehicle Specs'!D33 -> 102.05147 | G21: =0.5*'Vehicle Specs'!D54*'Vehicle Specs'!D55*'Vehicle Specs'!D50*B21^2 -> 70.465856 | H21: =MAX(E21-F21-G21, 0) -> 1248.0061 | I21: =IF(H21>0, H21/C$7, 0) -> 1.7995243 | J21: =IF(H21=0,"Cannot accel",IF(C21<=D21,"Torque","Power")) -> Power | K21: =B21-B20 -> 1.3888889 | L21: =IF(I21+I20>0, 2*K21/(I21+I20), 999) -> 0.72226228 | M21: =M20+L21 -> 4.3506102
A22: 55 | B22: =MAX(A22/3.6, 0.1) -> 15.277778 | C22: =C$6*'Vehicle Specs'!D30*'Vehicle Specs'!D31/'Vehicle Specs'!D29 -> 3113.4447 | D22: =C$5*1000*'Vehicle Specs'!D31/B22 -> 1291.3849 | E22: =MIN(C22,D22) -> 1291.3849 | F22: ='Vehicle Specs'!D32*C$7*'Vehicle Specs'!D33 -> 102.05147 | G22: =0.5*'Vehicle Specs'!D54*'Vehicle Specs'!D55*'Vehicle Specs'!D50*B22^2 -> 85.263686 | H22: =MAX(E22-F22-G22, 0) -> 1104.0698 | I22: =IF(H22>0, H22/C$7, 0) -> 1.5919797 | J22: =IF(H22=0,"Cannot accel",IF(C22<=D22,"Torque","Power")) -> Power | K22: =B22-B21 -> 1.3888889 | L22: =IF(I22+I21>0, 2*K22/(I22+I21), 999) -> 0.81904008 | M22: =M21+L22 -> 5.1696502
A23: 60 | B23: =MAX(A23/3.6, 0.1) -> 16.666667 | C23: =C$6*'Vehicle Specs'!D30*'Vehicle Specs'!D31/'Vehicle Specs'!D29 -> 3113.4447 | D23: =C$5*1000*'Vehicle Specs'!D31/B23 -> 1183.7695 | E23: =MIN(C23,D23) -> 1183.7695 | F23: ='Vehicle Specs'!D32*C$7*'Vehicle Specs'!D33 -> 102.05147 | G23: =0.5*'Vehicle Specs'!D54*'Vehicle Specs'!D55*'Vehicle Specs'!D50*B23^2 -> 101.47083 | H23: =MAX(E23-F23-G23, 0) -> 980.24723 | I23: =IF(H23>0, H23/C$7, 0) -> 1.4134376 | J23: =IF(H23=0,"Cannot accel",IF(C23<=D23,"Torque","Power")) -> Power | K23: =B23-B22 -> 1.3888889 | L23: =IF(I23+I22>0, 2*K23/(I23+I22), 999) -> 0.92425693 | M23: =M22+L23 -> 6.0939072
A24: 65 | B24: =MAX(A24/3.6, 0.1) -> 18.055556 | C24: =C$6*'Vehicle Specs'!D30*'Vehicle Specs'!D31/'Vehicle Specs'!D29 -> 3113.4447 | D24: =C$5*1000*'Vehicle Specs'!D31/B24 -> 1092.7103 | E24: =MIN(C24,D24) -> 1092.7103 | F24: ='Vehicle Specs'!D32*C$7*'Vehicle Specs'!D33 -> 102.05147 | G24: =0.5*'Vehicle Specs'!D54*'Vehicle Specs'!D55*'Vehicle Specs'!D50*B24^2 -> 119.0873 | H24: =MAX(E24-F24-G24, 0) -> 871.57157 | I24: =IF(H24>0, H24/C$7, 0) -> 1.256736 | J24: =IF(H24=0,"Cannot accel",IF(C24<=D24,"Torque","Power")) -> Power | K24: =B24-B23 -> 1.3888889 | L24: =IF(I24+I23>0, 2*K24/(I24+I23), 999) -> 1.0402986 | M24: =M23+L24 -> 7.1342057
A25: 70 | B25: =MAX(A25/3.6, 0.1) -> 19.444444 | C25: =C$6*'Vehicle Specs'!D30*'Vehicle Specs'!D31/'Vehicle Specs'!D29 -> 3113.4447 | D25: =C$5*1000*'Vehicle Specs'!D31/B25 -> 1014.6596 | E25: =MIN(C25,D25) -> 1014.6596 | F25: ='Vehicle Specs'!D32*C$7*'Vehicle Specs'!D33 -> 102.05147 | G25: =0.5*'Vehicle Specs'!D54*'Vehicle Specs'!D55*'Vehicle Specs'!D50*B25^2 -> 138.11308 | H25: =MAX(E25-F25-G25, 0) -> 774.49505 | I25: =IF(H25>0, H25/C$7, 0) -> 1.1167595 | J25: =IF(H25=0,"Cannot accel",IF(C25<=D25,"Torque","Power")) -> Power | K25: =B25-B24 -> 1.3888889 | L25: =IF(I25+I24>0, 2*K25/(I25+I24), 999) -> 1.170332 | M25: =M24+L25 -> 8.3045377
A27: ACHIEVABLE ACCELERATION PERFORMANCE
A28: Target | C28: Achievable Time | E28: seconds | M28: Remarks
A29: 0 → 20 km/h | C29: =M15 -> 1.2580551 | E29: seconds | M29: Time to reach 20 km/h with rated motor
A30: 0 → 30 km/h | C30: =M17 -> 1.9830367 | E30: seconds | M30: Time to reach 30 km/h with rated motor
A31: 0 → 40 km/h | C31: =M19 -> 2.9962574 | E31: seconds | M31: Time to reach 40 km/h with rated motor
A32: 0 → 50 km/h | C32: =M21 -> 4.3506102 | E32: seconds | M32: Time to reach 50 km/h with rated motor
A33: 0 → 60 km/h | C33: =M23 -> 6.0939072 | E33: seconds | M33: Time to reach 60 km/h with rated motor
A34: 0 → 70 km/h | C34: =M25 -> 8.3045377 | E34: seconds | M34: Time to reach 70 km/h with rated motor
A36: Approx Top Speed | C36: =LOOKUP(2,1/(H11:H25>0),A11:A25) -> 70 | E36: km/h | M36: Last speed where net force remains positive

Sheet Grade Verification
A1: Gradeability verification using rated motor specifications. Checks if the selected motor can handle grade requirements.
A3: RATED MOTOR SPECIFICATIONS (from Powertrain Summary)
A4: Parameter | B4: Unit | C4: Value | I4: Remarks
A5: Peak Motor Power (rated) | B5: kW | C5: ='Powertrain Summary'!E26 -> 22.419878 | I5: Rated peak power from SOR
A6: Peak Motor Torque (rated) | B6: Nm | C6: ='Powertrain Summary'!E28 -> 85.501797 | I6: Rated peak torque from SOR
A7: GVW (full load) | B7: kg | C7: ='Vehicle Specs'!D17 -> 843.52 | I7: Maximum loaded vehicle weight
A8: Wheel Radius | B8: m | C8: ='Vehicle Specs'!D29 -> 0.29 | I8: Effective tyre rolling radius
A9: Gear Ratio | B9: :1 | C9: ='Vehicle Specs'!D30 -> 12 | I9: Motor-to-wheel reduction ratio
A10: Powertrain Efficiency | C10: ='Vehicle Specs'!D31 -> 0.88 | I10: Combined drivetrain efficiency
A11: Rolling Resistance | C11: ='Vehicle Specs'!D32 -> 0.015 | I11: tyre-road friction coefficient
A12: Gravity | B12: m/s² | C12: ='Vehicle Specs'!D33 -> 9.81 | I12: Gravitational acceleration
A13: Design Grade Angle | B13: ° | C13: ='Vehicle Specs'!D37 -> 15 | I13: Target grade angle from vehicle specs
A14: Design Grade Speed | B14: km/h | C14: ='Vehicle Specs'!D38 -> 5 | I14: Target climbing speed
A15: Startup Acceleration | B15: m/s² | C15: ='Vehicle Specs'!D41 -> 0.5 | I15: Acceleration for hill start
A16: Static Friction Factor | C16: ='Vehicle Specs'!D42 -> 1.2 | I16: Breakaway friction multiplier
A18: AVAILABLE TRACTIVE FORCE FROM RATED MOTOR
A19: Parameter | B19: Symbol | C19: Unit | D19: Value | E19: Formula | I19: Remarks
A20: Max Tractive Force (torque) | B20: F_motor | C20: N | D20: =C6*C9*C10/C8 -> 3113.4447 | E20: T*i*eta/r | I20: Maximum force at wheel from rated motor torque
A21: Grade Speed | B21: v | C21: m/s | D21: =C14/3.6 -> 1.3888889 | I21: Target climbing speed in m/s
A22: Max Tractive Force (power) | B22: F_power | C22: N | D22: =C5*1000*C10/D21 -> 14205.234 | E22: P*eta/v | I22: Force limited by rated power at grade speed
A23: Available Tractive Force | B23: F_avail | C23: N | D23: =MIN(D20,D22) -> 3113.4447 | E23: MIN(F_torque, F_power) | I23: Actual available force (lesser of torque and power limits)
A25: SUSTAINED CLIMBING VERIFICATION (at design grade)
A26: Parameter | B26: Symbol | C26: Unit | D26: Value | E26: Formula | I26: Remarks
A27: Grade Angle | B27: theta | C27: rad | D27: =RADIANS(C13) -> 0.26179939 | I27: Design grade in radians
A28: Grade Resistance | B28: Fg | C28: N | D28: =C7*C12*SIN(D27) -> 2141.7098 | E28: GVW*g*sin(theta) | I28: Gravity force pulling vehicle down slope
A29: Rolling Resistance | B29: Fr | C29: N | D29: =C11*C7*C12*COS(D27) -> 119.89455 | E29: Crr*GVW*g*cos(theta) | I29: Rolling friction on grade
A30: Required Tractive Force (climb) | B30: Ft_req | C30: N | D30: =D28+D29 -> 2261.6043 | E30: Fg + Fr | I30: Total resistance for sustained climbing
A31: Surplus Force | B31: F_surplus | C31: N | D31: =D23-D30 -> 851.8404 | E31: F_avail - Ft_req | I31: Positive = motor can handle the grade
A32: Torque Margin (climb) | C32: % | D32: =D31/D30*100 -> 37.665315 | E32: (surplus/required)*100 | I32: Safety margin above minimum requirement
A33: Climb Verdict | D33: =IF(D31>0,"PASS - Motor can climb design grade","FAIL - Insufficient torque") -> PASS - Motor can climb design grade | I33: Whether rated motor meets sustained climb requirement
A35: STARTUP ON GRADE VERIFICATION (peak, starting from rest)
A36: Parameter | B36: Symbol | C36: Unit | D36: Value | E36: Formula | I36: Remarks
A37: Static Rolling Resistance | B37: Fr_s | C37: N | D37: =D29*C16 -> 143.87346 | E37: Fr * k_static | I37: Higher breakaway friction when starting from rest
A38: Acceleration Force | B38: Fa | C38: N | D38: =C7*C15 -> 421.76 | E38: GVW * a_start | I38: Force to accelerate from standstill on slope
A39: Required Startup Force | B39: Ft_start | C39: N | D39: =D28+D37+D38 -> 2707.3432 | E39: Fg + Fr_s + Fa | I39: Total force for worst-case hill start
A40: Surplus Force (startup) | C40: N | D40: =D20-D39 -> 406.10149 | E40: F_motor - Ft_start | I40: Positive = motor can start on grade
A41: Startup Margin | C41: % | D41: =D40/D39*100 -> 15 | E41: (surplus/required)*100 | I41: Safety margin for hill start
A42: Startup Verdict | D42: =IF(D40>0,"PASS - Motor can start on design grade","FAIL - Insufficient peak torque") -> PASS - Motor can start on design grade | I42: Whether rated motor meets hill start requirement
A44: MAXIMUM ACHIEVABLE GRADE (with rated motor)
A45: Parameter | B45: Symbol | C45: Unit | D45: Value | E45: Formula | I45: Remarks
...
